INFO 2019-07-15 14:12:17,140 basehttp 154 "GET / HTTP/1.1" 200 1712
INFO 2019-07-15 14:12:17,169 basehttp 154 "GET /static/media/search.png HTTP/1.1" 200 36238
INFO 2019-07-15 14:12:17,172 basehttp 154 "GET /static/media/lant.jpg HTTP/1.1" 200 216973
INFO 2019-07-15 14:12:17,268 basehttp 154 "GET /static/media/favicon.ico HTTP/1.1" 200 48702
INFO 2019-07-15 14:14:11,668 basehttp 154 "GET /user/login HTTP/1.1" 301 0
INFO 2019-07-15 14:14:11,681 basehttp 154 "GET /user/login/ HTTP/1.1" 200 2002
INFO 2019-07-15 14:14:20,607 basehttp 154 "POST /user/login/ HTTP/1.1" 200 42
WARNING 2019-07-15 14:14:20,631 log 228 Not Found: /favicon.ico
WARNING 2019-07-15 14:14:20,631 basehttp 154 "GET /favicon.ico HTTP/1.1" 404 2711
INFO 2019-07-15 14:14:22,532 basehttp 154 "GET /user/login/ HTTP/1.1" 200 2002
INFO 2019-07-15 14:15:46,936 basehttp 154 "GET /user/login/ HTTP/1.1" 200 2029
INFO 2019-07-15 14:15:48,723 basehttp 154 "GET /user/login/ HTTP/1.1" 200 2029
INFO 2019-07-15 14:15:48,750 basehttp 154 "GET /static/media/favicon.ico HTTP/1.1" 200 48702
INFO 2019-07-15 14:16:25,651 basehttp 154 "GET /user/login/ HTTP/1.1" 200 2003
INFO 2019-07-15 14:16:25,671 basehttp 154 "GET /static/media/favicon.ico HTTP/1.1" 200 48702
INFO 2019-07-15 14:16:43,789 basehttp 154 "GET /user/login/ HTTP/1.1" 200 1999
INFO 2019-07-15 14:16:43,812 basehttp 154 "GET /static/media/favicon.ico HTTP/1.1" 200 48702
INFO 2019-07-15 14:18:20,870 basehttp 154 "GET /user/login/ HTTP/1.1" 200 2054
INFO 2019-07-15 14:18:20,913 basehttp 154 "GET /static/media/favicon.ico HTTP/1.1" 200 48702
INFO 2019-07-15 14:18:31,510 basehttp 154 "GET /user/login/ HTTP/1.1" 200 2062
INFO 2019-07-15 14:18:31,547 basehttp 154 "GET /static/media/favicon.ico HTTP/1.1" 200 48702
INFO 2019-07-15 14:19:40,770 basehttp 154 "GET /user/login/ HTTP/1.1" 200 2138
INFO 2019-07-15 14:19:40,806 basehttp 154 "GET /static/media/favicon.ico HTTP/1.1" 200 48702
INFO 2019-07-15 14:19:41,506 basehttp 154 "GET /user/login/ HTTP/1.1" 200 2138
INFO 2019-07-15 14:19:41,543 basehttp 154 "GET /static/media/favicon.ico HTTP/1.1" 200 48702
INFO 2019-07-15 14:20:36,130 basehttp 154 "GET /user/login/ HTTP/1.1" 200 2172
INFO 2019-07-15 14:20:36,181 basehttp 154 "GET /static/media/favicon.ico HTTP/1.1" 200 48702
INFO 2019-07-15 14:21:06,773 basehttp 154 "GET /user/login/ HTTP/1.1" 200 2168
INFO 2019-07-15 14:21:06,813 basehttp 154 "GET /static/media/favicon.ico HTTP/1.1" 200 48702
INFO 2019-07-15 14:21:15,789 basehttp 154 "GET /user/login/ HTTP/1.1" 200 2172
INFO 2019-07-15 14:21:15,835 basehttp 154 "GET /static/media/favicon.ico HTTP/1.1" 200 48702
INFO 2019-07-15 14:21:34,017 basehttp 154 "GET /user/login/ HTTP/1.1" 200 2091
INFO 2019-07-15 14:21:34,061 basehttp 154 "GET /static/media/favicon.ico HTTP/1.1" 200 48702
INFO 2019-07-15 14:24:27,837 basehttp 154 "GET /user/login/ HTTP/1.1" 200 2092
INFO 2019-07-15 14:24:27,906 basehttp 154 "GET /static/media/bcg1.jpg HTTP/1.1" 200 260080
INFO 2019-07-15 14:24:27,931 basehttp 154 "GET /static/media/favicon.ico HTTP/1.1" 200 48702
INFO 2019-07-15 14:24:29,170 basehttp 154 "GET /user/login/ HTTP/1.1" 200 2092
INFO 2019-07-15 14:24:29,220 basehttp 154 "GET /static/media/favicon.ico HTTP/1.1" 200 48702
INFO 2019-07-15 14:24:54,582 basehttp 154 "POST /user/login/ HTTP/1.1" 200 42
INFO 2019-07-15 14:24:56,405 basehttp 154 "GET /user/login/ HTTP/1.1" 200 2092
INFO 2019-07-15 14:26:33,386 basehttp 154 "GET /user/login/ HTTP/1.1" 200 2113
INFO 2019-07-15 14:26:33,420 basehttp 154 "GET /static/media/favicon.ico HTTP/1.1" 200 48702
INFO 2019-07-15 14:26:34,592 basehttp 154 "POST /user/login/ HTTP/1.1" 200 42
INFO 2019-07-15 14:26:36,350 basehttp 154 "GET /user/login/ HTTP/1.1" 200 2113
INFO 2019-07-15 14:26:41,542 basehttp 154 "POST /user/login/ HTTP/1.1" 200 42
INFO 2019-07-15 14:26:43,331 basehttp 154 "GET /user/login/ HTTP/1.1" 200 2113
INFO 2019-07-15 14:27:24,621 basehttp 154 "POST /user/login/ HTTP/1.1" 200 42
INFO 2019-07-15 14:28:27,467 basehttp 154 "POST /user/login/ HTTP/1.1" 200 42
INFO 2019-07-15 14:28:28,706 basehttp 154 "GET /user/login/ HTTP/1.1" 200 2085
INFO 2019-07-15 14:28:30,121 basehttp 154 "GET /user/login/ HTTP/1.1" 200 2085
INFO 2019-07-15 14:28:30,149 basehttp 154 "GET /static/media/favicon.ico HTTP/1.1" 200 48702
INFO 2019-07-15 14:28:30,662 basehttp 154 "GET /user/login/ HTTP/1.1" 200 2085
INFO 2019-07-15 14:28:30,682 basehttp 154 "GET /static/media/favicon.ico HTTP/1.1" 200 48702
INFO 2019-07-15 14:28:36,145 basehttp 154 "GET /user/login/ HTTP/1.1" 200 2085
INFO 2019-07-15 14:28:36,180 basehttp 154 "GET /static/media/favicon.ico HTTP/1.1" 200 48702
INFO 2019-07-15 14:28:49,705 basehttp 154 "GET /user/register HTTP/1.1" 301 0
INFO 2019-07-15 14:28:49,709 basehttp 154 "GET /user/register/ HTTP/1.1" 200 9012
INFO 2019-07-15 14:29:08,583 basehttp 154 "POST /user/register/ HTTP/1.1" 200 1712
INFO 2019-07-15 14:33:59,892 basehttp 154 "GET /user/register/ HTTP/1.1" 200 9012
INFO 2019-07-15 14:34:16,905 basehttp 154 "POST /user/register/ HTTP/1.1" 200 1712
INFO 2019-07-15 14:34:16,974 basehttp 154 "GET /static/media/favicon.ico HTTP/1.1" 200 48702
ERROR 2019-07-15 14:52:45,220 log 228 Internal Server Error: /user/register/
Traceback (most recent call last):
  File "C:\Users\ŒÃ—ß∫¿\AppData\Local\Programs\Python\Python36\lib\site-packages\django\db\backends\utils.py", line 85, in _execute
    return self.cursor.execute(sql, params)
  File "C:\Users\ŒÃ—ß∫¿\AppData\Local\Programs\Python\Python36\lib\site-packages\django\db\backends\mysql\base.py", line 71, in execute
    return self.cursor.execute(query, args)
  File "C:\Users\ŒÃ—ß∫¿\AppData\Roaming\Python\Python36\site-packages\pymysql\cursors.py", line 170, in execute
    result = self._query(query)
  File "C:\Users\ŒÃ—ß∫¿\AppData\Roaming\Python\Python36\site-packages\pymysql\cursors.py", line 328, in _query
    conn.query(q)
  File "C:\Users\ŒÃ—ß∫¿\AppData\Roaming\Python\Python36\site-packages\pymysql\connections.py", line 516, in query
    self._affected_rows = self._read_query_result(unbuffered=unbuffered)
  File "C:\Users\ŒÃ—ß∫¿\AppData\Roaming\Python\Python36\site-packages\pymysql\connections.py", line 727, in _read_query_result
    result.read()
  File "C:\Users\ŒÃ—ß∫¿\AppData\Roaming\Python\Python36\site-packages\pymysql\connections.py", line 1066, in read
    first_packet = self.connection._read_packet()
  File "C:\Users\ŒÃ—ß∫¿\AppData\Roaming\Python\Python36\site-packages\pymysql\connections.py", line 683, in _read_packet
    packet.check_error()
  File "C:\Users\ŒÃ—ß∫¿\AppData\Roaming\Python\Python36\site-packages\pymysql\protocol.py", line 220, in check_error
    err.raise_mysql_exception(self._data)
  File "C:\Users\ŒÃ—ß∫¿\AppData\Roaming\Python\Python36\site-packages\pymysql\err.py", line 109, in raise_mysql_exception
    raise errorclass(errno, errval)
pymysql.err.IntegrityError: (1062, "Duplicate entry 'wengxuehao001' for key 'username'")

The above exception was the direct cause of the following exception:

Traceback (most recent call last):
  File "C:\Users\ŒÃ—ß∫¿\AppData\Local\Programs\Python\Python36\lib\site-packages\django\core\handlers\exception.py", line 34, in inner
    response = get_response(request)
  File "C:\Users\ŒÃ—ß∫¿\AppData\Local\Programs\Python\Python36\lib\site-packages\django\core\handlers\base.py", line 126, in _get_response
    response = self.process_exception_by_middleware(e, request)
  File "C:\Users\ŒÃ—ß∫¿\AppData\Local\Programs\Python\Python36\lib\site-packages\django\core\handlers\base.py", line 124, in _get_response
    response = wrapped_callback(request, *callback_args, **callback_kwargs)
  File "C:\Users\ŒÃ—ß∫¿\AppData\Local\Programs\Python\Python36\lib\site-packages\django\views\generic\base.py", line 68, in view
    return self.dispatch(request, *args, **kwargs)
  File "C:\Users\ŒÃ—ß∫¿\AppData\Local\Programs\Python\Python36\lib\site-packages\django\views\generic\base.py", line 88, in dispatch
    return handler(request, *args, **kwargs)
  File "D:\wxh\shiwu\apps\users\views.py", line 64, in post
    user.save()
  File "C:\Users\ŒÃ—ß∫¿\AppData\Local\Programs\Python\Python36\lib\site-packages\django\contrib\auth\base_user.py", line 73, in save
    super().save(*args, **kwargs)
  File "C:\Users\ŒÃ—ß∫¿\AppData\Local\Programs\Python\Python36\lib\site-packages\django\db\models\base.py", line 718, in save
    force_update=force_update, update_fields=update_fields)
  File "C:\Users\ŒÃ—ß∫¿\AppData\Local\Programs\Python\Python36\lib\site-packages\django\db\models\base.py", line 748, in save_base
    updated = self._save_table(raw, cls, force_insert, force_update, using, update_fields)
  File "C:\Users\ŒÃ—ß∫¿\AppData\Local\Programs\Python\Python36\lib\site-packages\django\db\models\base.py", line 831, in _save_table
    result = self._do_insert(cls._base_manager, using, fields, update_pk, raw)
  File "C:\Users\ŒÃ—ß∫¿\AppData\Local\Programs\Python\Python36\lib\site-packages\django\db\models\base.py", line 869, in _do_insert
    using=using, raw=raw)
  File "C:\Users\ŒÃ—ß∫¿\AppData\Local\Programs\Python\Python36\lib\site-packages\django\db\models\manager.py", line 82, in manager_method
    return getattr(self.get_queryset(), name)(*args, **kwargs)
  File "C:\Users\ŒÃ—ß∫¿\AppData\Local\Programs\Python\Python36\lib\site-packages\django\db\models\query.py", line 1136, in _insert
    return query.get_compiler(using=using).execute_sql(return_id)
  File "C:\Users\ŒÃ—ß∫¿\AppData\Local\Programs\Python\Python36\lib\site-packages\django\db\models\sql\compiler.py", line 1289, in execute_sql
    cursor.execute(sql, params)
  File "C:\Users\ŒÃ—ß∫¿\AppData\Local\Programs\Python\Python36\lib\site-packages\django\db\backends\utils.py", line 100, in execute
    return super().execute(sql, params)
  File "C:\Users\ŒÃ—ß∫¿\AppData\Local\Programs\Python\Python36\lib\site-packages\django\db\backends\utils.py", line 68, in execute
    return self._execute_with_wrappers(sql, params, many=False, executor=self._execute)
  File "C:\Users\ŒÃ—ß∫¿\AppData\Local\Programs\Python\Python36\lib\site-packages\django\db\backends\utils.py", line 77, in _execute_with_wrappers
    return executor(sql, params, many, context)
  File "C:\Users\ŒÃ—ß∫¿\AppData\Local\Programs\Python\Python36\lib\site-packages\django\db\backends\utils.py", line 85, in _execute
    return self.cursor.execute(sql, params)
  File "C:\Users\ŒÃ—ß∫¿\AppData\Local\Programs\Python\Python36\lib\site-packages\django\db\utils.py", line 89, in __exit__
    raise dj_exc_value.with_traceback(traceback) from exc_value
  File "C:\Users\ŒÃ—ß∫¿\AppData\Local\Programs\Python\Python36\lib\site-packages\django\db\backends\utils.py", line 85, in _execute
    return self.cursor.execute(sql, params)
  File "C:\Users\ŒÃ—ß∫¿\AppData\Local\Programs\Python\Python36\lib\site-packages\django\db\backends\mysql\base.py", line 71, in execute
    return self.cursor.execute(query, args)
  File "C:\Users\ŒÃ—ß∫¿\AppData\Roaming\Python\Python36\site-packages\pymysql\cursors.py", line 170, in execute
    result = self._query(query)
  File "C:\Users\ŒÃ—ß∫¿\AppData\Roaming\Python\Python36\site-packages\pymysql\cursors.py", line 328, in _query
    conn.query(q)
  File "C:\Users\ŒÃ—ß∫¿\AppData\Roaming\Python\Python36\site-packages\pymysql\connections.py", line 516, in query
    self._affected_rows = self._read_query_result(unbuffered=unbuffered)
  File "C:\Users\ŒÃ—ß∫¿\AppData\Roaming\Python\Python36\site-packages\pymysql\connections.py", line 727, in _read_query_result
    result.read()
  File "C:\Users\ŒÃ—ß∫¿\AppData\Roaming\Python\Python36\site-packages\pymysql\connections.py", line 1066, in read
    first_packet = self.connection._read_packet()
  File "C:\Users\ŒÃ—ß∫¿\AppData\Roaming\Python\Python36\site-packages\pymysql\connections.py", line 683, in _read_packet
    packet.check_error()
  File "C:\Users\ŒÃ—ß∫¿\AppData\Roaming\Python\Python36\site-packages\pymysql\protocol.py", line 220, in check_error
    err.raise_mysql_exception(self._data)
  File "C:\Users\ŒÃ—ß∫¿\AppData\Roaming\Python\Python36\site-packages\pymysql\err.py", line 109, in raise_mysql_exception
    raise errorclass(errno, errval)
django.db.utils.IntegrityError: (1062, "Duplicate entry 'wengxuehao001' for key 'username'")
ERROR 2019-07-15 14:52:45,230 basehttp 154 "POST /user/register/ HTTP/1.1" 500 233936
INFO 2019-07-15 14:52:51,590 basehttp 154 "GET /user/register/ HTTP/1.1" 200 9012
INFO 2019-07-15 14:52:52,332 basehttp 154 "GET /static/media/favicon.ico HTTP/1.1" 200 48702
INFO 2019-07-15 14:52:56,645 basehttp 154 "GET / HTTP/1.1" 200 1718
INFO 2019-07-15 14:52:56,690 basehttp 154 "GET /static/media/favicon.ico HTTP/1.1" 200 48702
INFO 2019-07-15 14:53:02,632 basehttp 154 "GET /service/Voice/ HTTP/1.1" 200 426
INFO 2019-07-15 14:53:04,348 basehttp 154 "GET /voice/compose/ HTTP/1.1" 200 520
INFO 2019-07-15 14:53:17,597 basehttp 154 "GET /voice/compose/ HTTP/1.1" 200 520
INFO 2019-07-15 14:53:24,696 basehttp 154 "GET /service/Voice/ HTTP/1.1" 200 426
INFO 2019-07-15 14:53:27,610 basehttp 154 "GET /voice/compose/ HTTP/1.1" 200 520
ERROR 2019-07-15 14:53:42,840 log 228 Internal Server Error: /
Traceback (most recent call last):
  File "C:\Users\ŒÃ—ß∫¿\AppData\Local\Programs\Python\Python36\lib\site-packages\django\core\handlers\exception.py", line 34, in inner
    response = get_response(request)
  File "C:\Users\ŒÃ—ß∫¿\AppData\Local\Programs\Python\Python36\lib\site-packages\django\core\handlers\base.py", line 156, in _get_response
    response = self.process_exception_by_middleware(e, request)
  File "C:\Users\ŒÃ—ß∫¿\AppData\Local\Programs\Python\Python36\lib\site-packages\django\core\handlers\base.py", line 154, in _get_response
    response = response.render()
  File "C:\Users\ŒÃ—ß∫¿\AppData\Local\Programs\Python\Python36\lib\site-packages\django\template\response.py", line 106, in render
    self.content = self.rendered_content
  File "C:\Users\ŒÃ—ß∫¿\AppData\Local\Programs\Python\Python36\lib\site-packages\django\template\response.py", line 83, in rendered_content
    content = template.render(context, self._request)
  File "C:\Users\ŒÃ—ß∫¿\AppData\Local\Programs\Python\Python36\lib\site-packages\django\template\backends\django.py", line 61, in render
    return self.template.render(context)
  File "C:\Users\ŒÃ—ß∫¿\AppData\Local\Programs\Python\Python36\lib\site-packages\django\template\base.py", line 171, in render
    return self._render(context)
  File "C:\Users\ŒÃ—ß∫¿\AppData\Local\Programs\Python\Python36\lib\site-packages\django\template\base.py", line 163, in _render
    return self.nodelist.render(context)
  File "C:\Users\ŒÃ—ß∫¿\AppData\Local\Programs\Python\Python36\lib\site-packages\django\template\base.py", line 937, in render
    bit = node.render_annotated(context)
  File "C:\Users\ŒÃ—ß∫¿\AppData\Local\Programs\Python\Python36\lib\site-packages\django\template\base.py", line 904, in render_annotated
    return self.render(context)
  File "C:\Users\ŒÃ—ß∫¿\AppData\Local\Programs\Python\Python36\lib\site-packages\django\template\defaulttags.py", line 442, in render
    url = reverse(view_name, args=args, kwargs=kwargs, current_app=current_app)
  File "C:\Users\ŒÃ—ß∫¿\AppData\Local\Programs\Python\Python36\lib\site-packages\django\urls\base.py", line 90, in reverse
    return iri_to_uri(resolver._reverse_with_prefix(view, prefix, *args, **kwargs))
  File "C:\Users\ŒÃ—ß∫¿\AppData\Local\Programs\Python\Python36\lib\site-packages\django\urls\resolvers.py", line 622, in _reverse_with_prefix
    raise NoReverseMatch(msg)
django.urls.exceptions.NoReverseMatch: Reverse for 'Voice' not found. 'Voice' is not a valid view function or pattern name.
ERROR 2019-07-15 14:53:42,842 basehttp 154 "GET / HTTP/1.1" 500 118569
ERROR 2019-07-15 14:56:43,991 log 228 Internal Server Error: /
Traceback (most recent call last):
  File "C:\Users\ŒÃ—ß∫¿\AppData\Local\Programs\Python\Python36\lib\site-packages\django\core\handlers\exception.py", line 34, in inner
    response = get_response(request)
  File "C:\Users\ŒÃ—ß∫¿\AppData\Local\Programs\Python\Python36\lib\site-packages\django\core\handlers\base.py", line 156, in _get_response
    response = self.process_exception_by_middleware(e, request)
  File "C:\Users\ŒÃ—ß∫¿\AppData\Local\Programs\Python\Python36\lib\site-packages\django\core\handlers\base.py", line 154, in _get_response
    response = response.render()
  File "C:\Users\ŒÃ—ß∫¿\AppData\Local\Programs\Python\Python36\lib\site-packages\django\template\response.py", line 106, in render
    self.content = self.rendered_content
  File "C:\Users\ŒÃ—ß∫¿\AppData\Local\Programs\Python\Python36\lib\site-packages\django\template\response.py", line 83, in rendered_content
    content = template.render(context, self._request)
  File "C:\Users\ŒÃ—ß∫¿\AppData\Local\Programs\Python\Python36\lib\site-packages\django\template\backends\django.py", line 61, in render
    return self.template.render(context)
  File "C:\Users\ŒÃ—ß∫¿\AppData\Local\Programs\Python\Python36\lib\site-packages\django\template\base.py", line 171, in render
    return self._render(context)
  File "C:\Users\ŒÃ—ß∫¿\AppData\Local\Programs\Python\Python36\lib\site-packages\django\template\base.py", line 163, in _render
    return self.nodelist.render(context)
  File "C:\Users\ŒÃ—ß∫¿\AppData\Local\Programs\Python\Python36\lib\site-packages\django\template\base.py", line 937, in render
    bit = node.render_annotated(context)
  File "C:\Users\ŒÃ—ß∫¿\AppData\Local\Programs\Python\Python36\lib\site-packages\django\template\base.py", line 904, in render_annotated
    return self.render(context)
  File "C:\Users\ŒÃ—ß∫¿\AppData\Local\Programs\Python\Python36\lib\site-packages\django\template\defaulttags.py", line 442, in render
    url = reverse(view_name, args=args, kwargs=kwargs, current_app=current_app)
  File "C:\Users\ŒÃ—ß∫¿\AppData\Local\Programs\Python\Python36\lib\site-packages\django\urls\base.py", line 90, in reverse
    return iri_to_uri(resolver._reverse_with_prefix(view, prefix, *args, **kwargs))
  File "C:\Users\ŒÃ—ß∫¿\AppData\Local\Programs\Python\Python36\lib\site-packages\django\urls\resolvers.py", line 622, in _reverse_with_prefix
    raise NoReverseMatch(msg)
django.urls.exceptions.NoReverseMatch: Reverse for 'Voice' not found. 'Voice' is not a valid view function or pattern name.
ERROR 2019-07-15 14:56:43,994 basehttp 154 "GET / HTTP/1.1" 500 118569
ERROR 2019-07-15 14:58:08,328 log 228 Internal Server Error: /
Traceback (most recent call last):
  File "C:\Users\ŒÃ—ß∫¿\AppData\Local\Programs\Python\Python36\lib\site-packages\django\core\handlers\exception.py", line 34, in inner
    response = get_response(request)
  File "C:\Users\ŒÃ—ß∫¿\AppData\Local\Programs\Python\Python36\lib\site-packages\django\core\handlers\base.py", line 156, in _get_response
    response = self.process_exception_by_middleware(e, request)
  File "C:\Users\ŒÃ—ß∫¿\AppData\Local\Programs\Python\Python36\lib\site-packages\django\core\handlers\base.py", line 154, in _get_response
    response = response.render()
  File "C:\Users\ŒÃ—ß∫¿\AppData\Local\Programs\Python\Python36\lib\site-packages\django\template\response.py", line 106, in render
    self.content = self.rendered_content
  File "C:\Users\ŒÃ—ß∫¿\AppData\Local\Programs\Python\Python36\lib\site-packages\django\template\response.py", line 83, in rendered_content
    content = template.render(context, self._request)
  File "C:\Users\ŒÃ—ß∫¿\AppData\Local\Programs\Python\Python36\lib\site-packages\django\template\backends\django.py", line 61, in render
    return self.template.render(context)
  File "C:\Users\ŒÃ—ß∫¿\AppData\Local\Programs\Python\Python36\lib\site-packages\django\template\base.py", line 171, in render
    return self._render(context)
  File "C:\Users\ŒÃ—ß∫¿\AppData\Local\Programs\Python\Python36\lib\site-packages\django\template\base.py", line 163, in _render
    return self.nodelist.render(context)
  File "C:\Users\ŒÃ—ß∫¿\AppData\Local\Programs\Python\Python36\lib\site-packages\django\template\base.py", line 937, in render
    bit = node.render_annotated(context)
  File "C:\Users\ŒÃ—ß∫¿\AppData\Local\Programs\Python\Python36\lib\site-packages\django\template\base.py", line 904, in render_annotated
    return self.render(context)
  File "C:\Users\ŒÃ—ß∫¿\AppData\Local\Programs\Python\Python36\lib\site-packages\django\template\defaulttags.py", line 442, in render
    url = reverse(view_name, args=args, kwargs=kwargs, current_app=current_app)
  File "C:\Users\ŒÃ—ß∫¿\AppData\Local\Programs\Python\Python36\lib\site-packages\django\urls\base.py", line 90, in reverse
    return iri_to_uri(resolver._reverse_with_prefix(view, prefix, *args, **kwargs))
  File "C:\Users\ŒÃ—ß∫¿\AppData\Local\Programs\Python\Python36\lib\site-packages\django\urls\resolvers.py", line 622, in _reverse_with_prefix
    raise NoReverseMatch(msg)
django.urls.exceptions.NoReverseMatch: Reverse for 'Voice' not found. 'Voice' is not a valid view function or pattern name.
ERROR 2019-07-15 14:58:08,332 basehttp 154 "GET / HTTP/1.1" 500 118434
INFO 2019-07-15 14:59:04,699 basehttp 154 "GET / HTTP/1.1" 200 1718
INFO 2019-07-15 14:59:04,711 basehttp 154 "GET /static/media/search.png HTTP/1.1" 200 36238
INFO 2019-07-15 14:59:04,712 basehttp 154 "GET /static/media/lant.jpg HTTP/1.1" 200 216973
INFO 2019-07-15 14:59:04,763 basehttp 154 "GET /static/media/favicon.ico HTTP/1.1" 200 48702
